<?xml version="1.0" ?>
<!-- =================================================================================== -->
<!-- |    This document was autogenerated by xacro from Robotic.xacro                  | -->
<!-- |    EDITING THIS FILE BY HAND IS NOT RECOMMENDED                                 | -->
<!-- =================================================================================== -->
<robot name="Robotic">
  <material name="silver">
    <color rgba="0.700 0.700 0.700 1.000"/>
  </material>
  <ros2_control name="RoboticSystem" type="system">
    <hardware>
      <plugin>gz_ros2_control/GazeboSimSystem</plugin>
    </hardware>
    <joint name="rear_left_wheel_joint">
      <command_interface name="velocity"/>
      <state_interface name="position"/>
      <state_interface name="velocity"/>
    </joint>
    <joint name="rear_right_wheel_joint">
      <command_interface name="velocity"/>
      <state_interface name="position"/>
      <state_interface name="velocity"/>
    </joint>
    <joint name="blade_joint">
      <command_interface name="velocity"/>
      <state_interface name="position"/>
      <state_interface name="velocity"/>
    </joint>
  </ros2_control>
  <gazebo reference="base_link">
    <material>Gazebo/Silver</material>
    <mu1>0.2</mu1>
    <mu2>0.2</mu2>
    <self_collide>true</self_collide>
    <gravity>true</gravity>
  </gazebo>
  <gazebo reference="top_body_1">
    <material>Gazebo/Silver</material>
    <mu1>0.2</mu1>
    <mu2>0.2</mu2>
    <self_collide>true</self_collide>
  </gazebo>
  <gazebo reference="motherboard_1">
    <material>Gazebo/Silver</material>
    <mu1>0.2</mu1>
    <mu2>0.2</mu2>
    <self_collide>true</self_collide>
  </gazebo>
  <gazebo reference="imu_1">
    <material>Gazebo/Silver</material>
    <mu1>0.2</mu1>
    <mu2>0.2</mu2>
    <self_collide>true</self_collide>
  </gazebo>
  <gazebo reference="electronic_board_cover_1">
    <material>Gazebo/Silver</material>
    <mu1>0.2</mu1>
    <mu2>0.2</mu2>
    <self_collide>true</self_collide>
  </gazebo>
  <gazebo reference="switch_button_1">
    <material>Gazebo/Silver</material>
    <mu1>0.2</mu1>
    <mu2>0.2</mu2>
    <self_collide>true</self_collide>
  </gazebo>
  <gazebo reference="emergency_stop_button_1">
    <material>Gazebo/Silver</material>
    <mu1>0.2</mu1>
    <mu2>0.2</mu2>
    <self_collide>true</self_collide>
  </gazebo>
  <gazebo reference="battery_1">
    <material>Gazebo/Silver</material>
    <mu1>0.2</mu1>
    <mu2>0.2</mu2>
    <self_collide>true</self_collide>
  </gazebo>
  <gazebo reference="rear_tyre_motor_1">
    <material>Gazebo/Silver</material>
    <mu1>0.2</mu1>
    <mu2>0.2</mu2>
    <self_collide>true</self_collide>
  </gazebo>
  <gazebo reference="rear_tyre_motor_2">
    <material>Gazebo/Silver</material>
    <mu1>0.2</mu1>
    <mu2>0.2</mu2>
    <self_collide>true</self_collide>
  </gazebo>
  <gazebo reference="rear_tyre_1">
    <material>Gazebo/Silver</material>
    <mu1>0.2</mu1>
    <mu2>0.2</mu2>
    <self_collide>true</self_collide>
  </gazebo>
  <gazebo reference="rear_tyre_2">
    <material>Gazebo/Silver</material>
    <mu1>0.2</mu1>
    <mu2>0.2</mu2>
    <self_collide>true</self_collide>
  </gazebo>
  <gazebo reference="front_tyre_1">
    <material>Gazebo/Silver</material>
    <mu1>0.2</mu1>
    <mu2>0.2</mu2>
    <self_collide>true</self_collide>
  </gazebo>
  <gazebo reference="front_tyre_2">
    <material>Gazebo/Silver</material>
    <mu1>0.2</mu1>
    <mu2>0.2</mu2>
    <self_collide>true</self_collide>
  </gazebo>
  <gazebo reference="blade_motor_1">
    <material>Gazebo/Silver</material>
    <mu1>0.2</mu1>
    <mu2>0.2</mu2>
    <self_collide>true</self_collide>
  </gazebo>
  <gazebo reference="blade_1">
    <material>Gazebo/Silver</material>
    <mu1>0.2</mu1>
    <mu2>0.2</mu2>
    <self_collide>true</self_collide>
  </gazebo>
  <gazebo reference="odometer_1">
    <material>Gazebo/Silver</material>
    <mu1>0.2</mu1>
    <mu2>0.2</mu2>
    <self_collide>true</self_collide>
  </gazebo>
  <gazebo reference="odometer_2">
    <material>Gazebo/Silver</material>
    <mu1>0.2</mu1>
    <mu2>0.2</mu2>
    <self_collide>true</self_collide>
  </gazebo>
  <gazebo reference="odometer_cover_left_1">
    <material>Gazebo/Silver</material>
    <mu1>0.2</mu1>
    <mu2>0.2</mu2>
    <self_collide>true</self_collide>
  </gazebo>
  <gazebo reference="odometer_cover_right_1">
    <material>Gazebo/Silver</material>
    <mu1>0.2</mu1>
    <mu2>0.2</mu2>
    <self_collide>true</self_collide>
  </gazebo>
  <gazebo reference="LiDAR_1">
    <material>Gazebo/Silver</material>
    <mu1>0.2</mu1>
    <mu2>0.2</mu2>
    <self_collide>true</self_collide>
  </gazebo>
  <gazebo>
    <plugin filename="gz_ros2_control-system" name="gz_ros2_control::GazeboSimROS2ControlPlugin">
      <parameters>
      /home/hafiz/ros2_ws/src/lawnmover/config/controllers.yaml
    </parameters>
    </plugin>
  </gazebo>
  <link name="base_link">
    <inertial>
      <origin rpy="0 0 0" xyz="8.580581248920662e-06 -0.019542907387817107 0.03658552092693562"/>
      <mass value="34.93508217588316"/>
      <inertia ixx="1.904747" ixy="5.3e-05" ixz="-2.9e-05" iyy="1.007743" iyz="-0.091706" izz="2.764873"/>
    </inertial>
    <visual>
      <origin rpy="0 0 0" xyz="0 0 0"/>
      <geometry>
        <mesh filename="file:///home/hafiz/ros2_ws/install/lawnmover/share/lawnmover/meshes/base_link.stl" scale="0.001 0.001 0.001"/>
      </geometry>
      <material name="silver"/>
    </visual>
    <collision>
      <origin rpy="0 0 0" xyz="0 0 0"/>
      <geometry>
        <mesh filename="file:///home/hafiz/ros2_ws/install/lawnmover/share/lawnmover/meshes/base_link.stl" scale="0.001 0.001 0.001"/>
      </geometry>
    </collision>
  </link>
  <link name="top_body_1">
    <inertial>
      <origin rpy="0 0 0" xyz="0.017654980692551753 0.30786706240030465 0.06037211225105721"/>
      <mass value="9.919977078705204"/>
      <inertia ixx="0.219339" ixy="-0.0" ixz="0.0" iyy="0.194629" iyz="-0.012416" izz="0.363738"/>
    </inertial>
    <visual>
      <origin rpy="0 0 0" xyz="0.017655 0.2665 -0.166281"/>
      <geometry>
        <mesh filename="file:///home/hafiz/ros2_ws/install/lawnmover/share/lawnmover/meshes/top_body_1.stl" scale="0.001 0.001 0.001"/>
      </geometry>
      <material name="silver"/>
    </visual>
    <collision>
      <origin rpy="0 0 0" xyz="0.017655 0.2665 -0.166281"/>
      <geometry>
        <mesh filename="file:///home/hafiz/ros2_ws/install/lawnmover/share/lawnmover/meshes/top_body_1.stl" scale="0.001 0.001 0.001"/>
      </geometry>
    </collision>
  </link>
  <link name="motherboard_1">
    <inertial>
      <origin rpy="0 0 0" xyz="0.00018954971024159404 -0.04815671737909372 0.00182571346129895"/>
      <mass value="0.30547549443546346"/>
      <inertia ixx="0.000545" ixy="-1e-06" ixz="-0.0" iyy="0.00015" iyz="-1e-06" izz="0.000694"/>
    </inertial>
    <visual>
      <origin rpy="0 0 0" xyz="-0.000151 -0.041273 -0.198"/>
      <geometry>
        <mesh filename="file:///home/hafiz/ros2_ws/install/lawnmover/share/lawnmover/meshes/motherboard_1.stl" scale="0.001 0.001 0.001"/>
      </geometry>
      <material name="silver"/>
    </visual>
    <collision>
      <origin rpy="0 0 0" xyz="-0.000151 -0.041273 -0.198"/>
      <geometry>
        <mesh filename="file:///home/hafiz/ros2_ws/install/lawnmover/share/lawnmover/meshes/motherboard_1.stl" scale="0.001 0.001 0.001"/>
      </geometry>
    </collision>
  </link>
  <link name="imu_1">
    <inertial>
      <origin rpy="0 0 0" xyz="-2.2377820345726557e-17 -0.08499956692800073 0.00999999999999443"/>
      <mass value="0.32365124456773336"/>
      <inertia ixx="6.6e-05" ixy="-0.0" ixz="-0.0" iyy="6.6e-05" iyz="0.0" izz="0.000111"/>
    </inertial>
    <visual>
      <origin rpy="0 0 0" xyz="0.0 -0.205544 -0.198"/>
      <geometry>
        <mesh filename="file:///home/hafiz/ros2_ws/install/lawnmover/share/lawnmover/meshes/imu_1.stl" scale="0.001 0.001 0.001"/>
      </geometry>
      <material name="silver"/>
    </visual>
    <collision>
      <origin rpy="0 0 0" xyz="0.0 -0.205544 -0.198"/>
      <geometry>
        <mesh filename="file:///home/hafiz/ros2_ws/install/lawnmover/share/lawnmover/meshes/imu_1.stl" scale="0.001 0.001 0.001"/>
      </geometry>
    </collision>
  </link>
  <link name="electronic_board_cover_1">
    <inertial>
      <origin rpy="0 0 0" xyz="-8.390793912644897e-08 -0.15716523777900676 0.0010590757642855164"/>
      <mass value="2.0241142371386207"/>
      <inertia ixx="0.01662" ixy="0.0" ixz="-0.0" iyy="0.00385" iyz="2e-05" izz="0.020434"/>
    </inertial>
    <visual>
      <origin rpy="0 0 0" xyz="0.0 -0.209544 -0.195"/>
      <geometry>
        <mesh filename="file:///home/hafiz/ros2_ws/install/lawnmover/share/lawnmover/meshes/electronic_board_cover_1.stl" scale="0.001 0.001 0.001"/>
      </geometry>
      <material name="silver"/>
    </visual>
    <collision>
      <origin rpy="0 0 0" xyz="0.0 -0.209544 -0.195"/>
      <geometry>
        <mesh filename="file:///home/hafiz/ros2_ws/install/lawnmover/share/lawnmover/meshes/electronic_board_cover_1.stl" scale="0.001 0.001 0.001"/>
      </geometry>
    </collision>
  </link>
  <link name="switch_button_1">
    <inertial>
      <origin rpy="0 0 0" xyz="-5.556410329653242e-16 -0.012500000000032145 0.0071274180062225745"/>
      <mass value="0.19298374073034502"/>
      <inertia ixx="2.1e-05" ixy="0.0" ixz="-0.0" iyy="4.2e-05" iyz="-0.0" izz="4.4e-05"/>
    </inertial>
    <visual>
      <origin rpy="0 0 0" xyz="0.0 -0.0325 -0.270531"/>
      <geometry>
        <mesh filename="file:///home/hafiz/ros2_ws/install/lawnmover/share/lawnmover/meshes/switch_button_1.stl" scale="0.001 0.001 0.001"/>
      </geometry>
      <material name="silver"/>
    </visual>
    <collision>
      <origin rpy="0 0 0" xyz="0.0 -0.0325 -0.270531"/>
      <geometry>
        <mesh filename="file:///home/hafiz/ros2_ws/install/lawnmover/share/lawnmover/meshes/switch_button_1.stl" scale="0.001 0.001 0.001"/>
      </geometry>
    </collision>
  </link>
  <link name="emergency_stop_button_1">
    <inertial>
      <origin rpy="0 0 0" xyz="-1.1547058025862643e-15 -0.010000000000033142 0.0041020541199149885"/>
      <mass value="0.09548088941801776"/>
      <inertia ixx="7e-06" ixy="-0.0" ixz="-0.0" iyy="1.3e-05" iyz="0.0" izz="1.4e-05"/>
    </inertial>
    <visual>
      <origin rpy="0 0 0" xyz="0.0 0.0225 -0.270531"/>
      <geometry>
        <mesh filename="file:///home/hafiz/ros2_ws/install/lawnmover/share/lawnmover/meshes/emergency_stop_button_1.stl" scale="0.001 0.001 0.001"/>
      </geometry>
      <material name="silver"/>
    </visual>
    <collision>
      <origin rpy="0 0 0" xyz="0.0 0.0225 -0.270531"/>
      <geometry>
        <mesh filename="file:///home/hafiz/ros2_ws/install/lawnmover/share/lawnmover/meshes/emergency_stop_button_1.stl" scale="0.001 0.001 0.001"/>
      </geometry>
    </collision>
  </link>
  <link name="battery_1">
    <inertial>
      <origin rpy="0 0 0" xyz="1.3452806890719966e-16 -0.07721057389467109 0.007972698479452152"/>
      <mass value="10.0452810221613"/>
      <inertia ixx="0.019541" ixy="0.0" ixz="-0.0" iyy="0.040964" iyz="-0.002631" izz="0.057089"/>
    </inertial>
    <visual>
      <origin rpy="0 0 0" xyz="-0.0 -0.279116 -0.032315"/>
      <geometry>
        <mesh filename="file:///home/hafiz/ros2_ws/install/lawnmover/share/lawnmover/meshes/battery_1.stl" scale="0.001 0.001 0.001"/>
      </geometry>
      <material name="silver"/>
    </visual>
    <collision>
      <origin rpy="0 0 0" xyz="-0.0 -0.279116 -0.032315"/>
      <geometry>
        <mesh filename="file:///home/hafiz/ros2_ws/install/lawnmover/share/lawnmover/meshes/battery_1.stl" scale="0.001 0.001 0.001"/>
      </geometry>
    </collision>
  </link>
  <link name="rear_tyre_motor_1">
    <inertial>
      <origin rpy="0 0 0" xyz="0.04095050408351533 0.03540298157788521 0.032067539827467"/>
      <mass value="2.560524826080275"/>
      <inertia ixx="0.001763" ixy="-0.0" ixz="2e-06" iyy="0.00207" iyz="-0.000109" izz="0.002736"/>
    </inertial>
    <visual>
      <origin rpy="0 0 0" xyz="-0.1275 -0.188599 -0.01792"/>
      <geometry>
        <mesh filename="file:///home/hafiz/ros2_ws/install/lawnmover/share/lawnmover/meshes/rear_tyre_motor_1.stl" scale="0.001 0.001 0.001"/>
      </geometry>
      <material name="silver"/>
    </visual>
    <collision>
      <origin rpy="0 0 0" xyz="-0.1275 -0.188599 -0.01792"/>
      <geometry>
        <mesh filename="file:///home/hafiz/ros2_ws/install/lawnmover/share/lawnmover/meshes/rear_tyre_motor_1.stl" scale="0.001 0.001 0.001"/>
      </geometry>
    </collision>
  </link>
  <link name="rear_tyre_motor_2">
    <inertial>
      <origin rpy="0 0 0" xyz="-0.04095050408351539 -0.043604018422104096 0.019502539827468728"/>
      <mass value="2.560524826080275"/>
      <inertia ixx="0.001763" ixy="0.0" ixz="-2e-06" iyy="0.00207" iyz="-0.000109" izz="0.002736"/>
    </inertial>
    <visual>
      <origin rpy="0 0 0" xyz="0.1275 -0.267606 -0.030485"/>
      <geometry>
        <mesh filename="file:///home/hafiz/ros2_ws/install/lawnmover/share/lawnmover/meshes/rear_tyre_motor_2.stl" scale="0.001 0.001 0.001"/>
      </geometry>
      <material name="silver"/>
    </visual>
    <collision>
      <origin rpy="0 0 0" xyz="0.1275 -0.267606 -0.030485"/>
      <geometry>
        <mesh filename="file:///home/hafiz/ros2_ws/install/lawnmover/share/lawnmover/meshes/rear_tyre_motor_2.stl" scale="0.001 0.001 0.001"/>
      </geometry>
    </collision>
  </link>
  <link name="rear_tyre_1">
    <inertial>
      <origin rpy="0 0 0" xyz="0.04072419849369893 2.931116702131753e-08 5.5632352821688436e-09"/>
      <mass value="9.483268171490044"/>
      <inertia ixx="0.038711" ixy="0.0" ixz="0.0" iyy="0.021995" iyz="0.0" izz="0.021995"/>
    </inertial>
    <visual>
      <origin rpy="0 0 0" xyz="-0.2115 -0.224 -0.05"/>
      <geometry>
        <mesh filename="file:///home/hafiz/ros2_ws/install/lawnmover/share/lawnmover/meshes/rear_tyre_1.stl" scale="0.001 0.001 0.001"/>
      </geometry>
      <material name="silver"/>
    </visual>
    <collision>
      <origin rpy="0 0 0" xyz="-0.2115 -0.224 -0.05"/>
      <geometry>
        <mesh filename="file:///home/hafiz/ros2_ws/install/lawnmover/share/lawnmover/meshes/rear_tyre_1.stl" scale="0.001 0.001 0.001"/>
      </geometry>
    </collision>
  </link>
  <link name="rear_tyre_2">
    <inertial>
      <origin rpy="0 0 0" xyz="-0.46372419849369895 -2.9590921740707543e-08 -3.8041371927532985e-09"/>
      <mass value="9.483268171490044"/>
      <inertia ixx="0.038711" ixy="0.0" ixz="0.0" iyy="0.021995" iyz="-0.0" izz="0.021995"/>
    </inertial>
    <visual>
      <origin rpy="0 0 0" xyz="-0.2115 -0.224 -0.05"/>
      <geometry>
        <mesh filename="file:///home/hafiz/ros2_ws/install/lawnmover/share/lawnmover/meshes/rear_tyre_2.stl" scale="0.001 0.001 0.001"/>
      </geometry>
      <material name="silver"/>
    </visual>
    <collision>
      <origin rpy="0 0 0" xyz="-0.2115 -0.224 -0.05"/>
      <geometry>
        <mesh filename="file:///home/hafiz/ros2_ws/install/lawnmover/share/lawnmover/meshes/rear_tyre_2.stl" scale="0.001 0.001 0.001"/>
      </geometry>
    </collision>
  </link>
  <link name="front_tyre_1">
    <inertial>
      <origin rpy="0 0 0" xyz="4.163336342344337e-16 0.007185705204167586 -0.038621949502823105"/>
      <mass value="0.6297145300990463"/>
      <inertia ixx="0.000438" ixy="0.0" ixz="-0.0" iyy="0.000377" iyz="4.7e-05" izz="0.000187"/>
    </inertial>
    <visual>
      <origin rpy="0 0 0" xyz="-0.2025 0.234 -0.04"/>
      <geometry>
        <mesh filename="file:///home/hafiz/ros2_ws/install/lawnmover/share/lawnmover/meshes/front_tyre_1.stl" scale="0.001 0.001 0.001"/>
      </geometry>
      <material name="silver"/>
    </visual>
    <collision>
      <origin rpy="0 0 0" xyz="-0.2025 0.234 -0.04"/>
      <geometry>
        <mesh filename="file:///home/hafiz/ros2_ws/install/lawnmover/share/lawnmover/meshes/front_tyre_1.stl" scale="0.001 0.001 0.001"/>
      </geometry>
    </collision>
  </link>
  <link name="front_tyre_2">
    <inertial>
      <origin rpy="0 0 0" xyz="2.220446049250313e-16 0.007185705204167225 -0.0386219495028231"/>
      <mass value="0.6297145300990463"/>
      <inertia ixx="0.000438" ixy="0.0" ixz="-0.0" iyy="0.000377" iyz="4.7e-05" izz="0.000187"/>
    </inertial>
    <visual>
      <origin rpy="0 0 0" xyz="0.2025 0.234 -0.04"/>
      <geometry>
        <mesh filename="file:///home/hafiz/ros2_ws/install/lawnmover/share/lawnmover/meshes/front_tyre_2.stl" scale="0.001 0.001 0.001"/>
      </geometry>
      <material name="silver"/>
    </visual>
    <collision>
      <origin rpy="0 0 0" xyz="0.2025 0.234 -0.04"/>
      <geometry>
        <mesh filename="file:///home/hafiz/ros2_ws/install/lawnmover/share/lawnmover/meshes/front_tyre_2.stl" scale="0.001 0.001 0.001"/>
      </geometry>
    </collision>
  </link>
  <link name="blade_motor_1">
    <inertial>
      <origin rpy="0 0 0" xyz="0.045000000809822006 -0.07794243924366638 0.05768845947562536"/>
      <mass value="10.659680269011584"/>
      <inertia ixx="0.030799" ixy="0.0" ixz="0.0" iyy="0.030799" iyz="-0.0" izz="0.018905"/>
    </inertial>
    <visual>
      <origin rpy="0 0 0" xyz="0.045 0.032058 -0.0245"/>
      <geometry>
        <mesh filename="file:///home/hafiz/ros2_ws/install/lawnmover/share/lawnmover/meshes/blade_motor_1.stl" scale="0.001 0.001 0.001"/>
      </geometry>
      <material name="silver"/>
    </visual>
    <collision>
      <origin rpy="0 0 0" xyz="0.045 0.032058 -0.0245"/>
      <geometry>
        <mesh filename="file:///home/hafiz/ros2_ws/install/lawnmover/share/lawnmover/meshes/blade_motor_1.stl" scale="0.001 0.001 0.001"/>
      </geometry>
    </collision>
  </link>
  <link name="blade_1">
    <inertial>
      <origin rpy="0 0 0" xyz="-3.691323145453111e-08 1.1276890937716999e-07 0.0036574437329575035"/>
      <mass value="0.8089249216665014"/>
      <inertia ixx="0.002255" ixy="0.0" ixz="-0.0" iyy="0.002255" iyz="0.0" izz="0.004474"/>
    </inertial>
    <visual>
      <origin rpy="0 0 0" xyz="-0.0 0.11 0.0125"/>
      <geometry>
        <mesh filename="file:///home/hafiz/ros2_ws/install/lawnmover/share/lawnmover/meshes/blade_1.stl" scale="0.001 0.001 0.001"/>
      </geometry>
      <material name="silver"/>
    </visual>
    <collision>
      <origin rpy="0 0 0" xyz="-0.0 0.11 0.0125"/>
      <geometry>
        <mesh filename="file:///home/hafiz/ros2_ws/install/lawnmover/share/lawnmover/meshes/blade_1.stl" scale="0.001 0.001 0.001"/>
      </geometry>
    </collision>
  </link>
  <link name="odometer_1">
    <inertial>
      <origin rpy="0 0 0" xyz="0.007217520525320237 0.021291903054299288 0.007587551264943482"/>
      <mass value="0.05709594931006652"/>
      <inertia ixx="1.1e-05" ixy="1e-06" ixz="-0.0" iyy="3e-06" iyz="0.0" izz="1.1e-05"/>
    </inertial>
    <visual>
      <origin rpy="0 0 0" xyz="-0.227951 0.246486 -0.13"/>
      <geometry>
        <mesh filename="file:///home/hafiz/ros2_ws/install/lawnmover/share/lawnmover/meshes/odometer_1.stl" scale="0.001 0.001 0.001"/>
      </geometry>
      <material name="silver"/>
    </visual>
    <collision>
      <origin rpy="0 0 0" xyz="-0.227951 0.246486 -0.13"/>
      <geometry>
        <mesh filename="file:///home/hafiz/ros2_ws/install/lawnmover/share/lawnmover/meshes/odometer_1.stl" scale="0.001 0.001 0.001"/>
      </geometry>
    </collision>
  </link>
  <link name="odometer_2">
    <inertial>
      <origin rpy="0 0 0" xyz="0.010737113090464656 0.01975324377022028 0.007587551264943482"/>
      <mass value="0.05709594931006652"/>
      <inertia ixx="1.1e-05" ixy="-1e-06" ixz="0.0" iyy="3e-06" iyz="0.0" izz="1.1e-05"/>
    </inertial>
    <visual>
      <origin rpy="0 0 0" xyz="0.245886 0.244958 -0.13"/>
      <geometry>
        <mesh filename="file:///home/hafiz/ros2_ws/install/lawnmover/share/lawnmover/meshes/odometer_2.stl" scale="0.001 0.001 0.001"/>
      </geometry>
      <material name="silver"/>
    </visual>
    <collision>
      <origin rpy="0 0 0" xyz="0.245886 0.244958 -0.13"/>
      <geometry>
        <mesh filename="file:///home/hafiz/ros2_ws/install/lawnmover/share/lawnmover/meshes/odometer_2.stl" scale="0.001 0.001 0.001"/>
      </geometry>
    </collision>
  </link>
  <link name="odometer_cover_left_1">
    <inertial>
      <origin rpy="0 0 0" xyz="-0.0012109615756692171 -0.05130716466293511 0.013753515252000331"/>
      <mass value="0.0974690142224969"/>
      <inertia ixx="0.000144" ixy="-4e-06" ixz="3e-06" iyy="3.3e-05" iyz="-9e-06" izz="0.000155"/>
    </inertial>
    <visual>
      <origin rpy="0 0 0" xyz="-0.230379 0.164 -0.135"/>
      <geometry>
        <mesh filename="file:///home/hafiz/ros2_ws/install/lawnmover/share/lawnmover/meshes/odometer_cover_left_1.stl" scale="0.001 0.001 0.001"/>
      </geometry>
      <material name="silver"/>
    </visual>
    <collision>
      <origin rpy="0 0 0" xyz="-0.230379 0.164 -0.135"/>
      <geometry>
        <mesh filename="file:///home/hafiz/ros2_ws/install/lawnmover/share/lawnmover/meshes/odometer_cover_left_1.stl" scale="0.001 0.001 0.001"/>
      </geometry>
    </collision>
  </link>
  <link name="odometer_cover_right_1">
    <inertial>
      <origin rpy="0 0 0" xyz="0.0012109615756695502 -0.05130716466293639 0.013753515252000165"/>
      <mass value="0.09746901422249486"/>
      <inertia ixx="0.000144" ixy="4e-06" ixz="-3e-06" iyy="3.3e-05" iyz="-9e-06" izz="0.000155"/>
    </inertial>
    <visual>
      <origin rpy="0 0 0" xyz="0.230379 0.164 -0.135"/>
      <geometry>
        <mesh filename="file:///home/hafiz/ros2_ws/install/lawnmover/share/lawnmover/meshes/odometer_cover_right_1.stl" scale="0.001 0.001 0.001"/>
      </geometry>
      <material name="silver"/>
    </visual>
    <collision>
      <origin rpy="0 0 0" xyz="0.230379 0.164 -0.135"/>
      <geometry>
        <mesh filename="file:///home/hafiz/ros2_ws/install/lawnmover/share/lawnmover/meshes/odometer_cover_right_1.stl" scale="0.001 0.001 0.001"/>
      </geometry>
    </collision>
  </link>
  <link name="LiDAR_1">
    <inertial>
      <origin rpy="0 0 0" xyz="-0.026000000000035647 0.025999999999967827 0.030737618109065556"/>
      <mass value="1.910203205712103"/>
      <inertia ixx="0.001649" ixy="0.0" ixz="0.0" iyy="0.001649" iyz="-0.0" izz="0.000894"/>
    </inertial>
    <visual>
      <origin rpy="0 0 0" xyz="-0.026 -0.094 -0.270531"/>
      <geometry>
        <mesh filename="file:///home/hafiz/ros2_ws/install/lawnmover/share/lawnmover/meshes/LiDAR_1.stl" scale="0.001 0.001 0.001"/>
      </geometry>
      <material name="silver"/>
    </visual>
    <collision>
      <origin rpy="0 0 0" xyz="-0.026 -0.094 -0.270531"/>
      <geometry>
        <mesh filename="file:///home/hafiz/ros2_ws/install/lawnmover/share/lawnmover/meshes/LiDAR_1.stl" scale="0.001 0.001 0.001"/>
      </geometry>
    </collision>
  </link>
  <joint name="Rigid 1" type="fixed">
    <origin rpy="0 0 0" xyz="-0.017655 -0.2665 0.166281"/>
    <parent link="base_link"/>
    <child link="top_body_1"/>
  </joint>
  <joint name="Rigid 2" type="fixed">
    <origin rpy="0 0 0" xyz="0.000151 -0.168271 0.003"/>
    <parent link="electronic_board_cover_1"/>
    <child link="motherboard_1"/>
  </joint>
  <joint name="Rigid 3" type="fixed">
    <origin rpy="0 0 0" xyz="0.0 -0.004 0.003"/>
    <parent link="electronic_board_cover_1"/>
    <child link="imu_1"/>
  </joint>
  <joint name="Rigid 4" type="fixed">
    <origin rpy="0 0 0" xyz="0.017655 0.476044 0.028719"/>
    <parent link="top_body_1"/>
    <child link="electronic_board_cover_1"/>
  </joint>
  <joint name="Rigid 6" type="fixed">
    <origin rpy="0 0 0" xyz="0.017655 0.299 0.10425"/>
    <parent link="top_body_1"/>
    <child link="switch_button_1"/>
  </joint>
  <joint name="Rigid 7" type="fixed">
    <origin rpy="0 0 0" xyz="0.017655 0.244 0.10425"/>
    <parent link="top_body_1"/>
    <child link="emergency_stop_button_1"/>
  </joint>
  <joint name="Rigid 8" type="fixed">
    <origin rpy="0 0 0" xyz="0.0 0.279116 0.032315"/>
    <parent link="base_link"/>
    <child link="battery_1"/>
  </joint>
  <joint name="Rigid 9" type="fixed">
    <origin rpy="0 0 0" xyz="0.1275 0.188599 0.01792"/>
    <parent link="base_link"/>
    <child link="rear_tyre_motor_1"/>
  </joint>
  <joint name="Rigid 10" type="fixed">
    <origin rpy="0 0 0" xyz="-0.1275 0.267606 0.030485"/>
    <parent link="base_link"/>
    <child link="rear_tyre_motor_2"/>
  </joint>
  <joint name="rear_left_wheel_joint" type="continuous">
    <origin rpy="0 0 0" xyz="0.084 0.035401 0.03208"/>
    <parent link="rear_tyre_motor_1"/>
    <child link="rear_tyre_1"/>
    <axis xyz="1 0 0"/>
  </joint>
  <joint name="rear_right_wheel_joint" type="continuous">
    <origin rpy="0 0 0" xyz="0.339 -0.043606 0.019515"/>
    <parent link="rear_tyre_motor_2"/>
    <child link="rear_tyre_2"/>
    <axis xyz="1 0 0"/>
  </joint>
  <joint name="Rigid 13" type="fixed">
    <origin rpy="0 0 0" xyz="0.2025 -0.234 0.04"/>
    <parent link="base_link"/>
    <child link="front_tyre_1"/>
  </joint>
  <joint name="Rigid 14" type="fixed">
    <origin rpy="0 0 0" xyz="-0.2025 -0.234 0.04"/>
    <parent link="base_link"/>
    <child link="front_tyre_2"/>
  </joint>
  <joint name="Rigid 15" type="fixed">
    <origin rpy="0 0 0" xyz="-0.045 -0.032058 0.0245"/>
    <parent link="base_link"/>
    <child link="blade_motor_1"/>
  </joint>
  <joint name="blade_joint" type="continuous">
    <origin rpy="0 0 0" xyz="0.045 -0.077942 -0.037"/>
    <parent link="blade_motor_1"/>
    <child link="blade_1"/>
    <axis xyz="0 0 1"/>
  </joint>
  <joint name="Rigid 17" type="fixed">
    <origin rpy="0 0 0" xyz="0.227951 -0.246486 0.13"/>
    <parent link="base_link"/>
    <child link="odometer_1"/>
  </joint>
  <joint name="Rigid 18" type="fixed">
    <origin rpy="0 0 0" xyz="-0.245886 -0.244958 0.13"/>
    <parent link="base_link"/>
    <child link="odometer_2"/>
  </joint>
  <joint name="Rigid 19" type="fixed">
    <origin rpy="0 0 0" xyz="0.230379 -0.164 0.135"/>
    <parent link="base_link"/>
    <child link="odometer_cover_left_1"/>
  </joint>
  <joint name="Rigid 20" type="fixed">
    <origin rpy="0 0 0" xyz="-0.230379 -0.164 0.135"/>
    <parent link="base_link"/>
    <child link="odometer_cover_right_1"/>
  </joint>
  <joint name="Rigid 21" type="fixed">
    <origin rpy="0 0 0" xyz="0.043655 0.3605 0.10425"/>
    <parent link="top_body_1"/>
    <child link="LiDAR_1"/>
  </joint>
</robot>
